// operacao sincrona, sem erro

const assert = require('assert');

// const pushNumber = (list, number) => list.push(number);

// let numbers = [];

// pushNumber(numbers, 1);
// pushNumber(numbers, 2);
// pushNumber(numbers, 3);

// assert.deepStrictEqual(numbers, [1, 2, 3]);

// operacao assincrona, gera erro

// const pushNumber = (list, number) => list.push(number);

// let numbers = [];

// setTimeout(() => pushNumber(numbers, 1), 3000);
// pushNumber(numbers, 2);
// pushNumber(numbers, 3);

// console.log(numbers); // output [ 2, 3 ]

// assert.deepStrictEqual(numbers, [1, 2, 3]); // essa validação falha

// refatorando operacao assincrona afim de passar no teste

const pushNumber = (list, number) => {
  list.push(number);
  console.log(list);
};

let numbers = [];

setTimeout(() => pushNumber(numbers, 1), 3000);
pushNumber(numbers, 2);
pushNumber(numbers, 3);

setTimeout(() => assert.deepStrictEqual(numbers, [2, 3, 1]), 3000);